Traceback (most recent call last):
  File "/opt/hostedtoolcache/Python/3.11.11/x64/lib/python3.11/site-packages/jupyter_cache/executors/utils.py", line 58, in single_nb_execution
    executenb(
  File "/opt/hostedtoolcache/Python/3.11.11/x64/lib/python3.11/site-packages/nbclient/client.py", line 1319, in execute
    return NotebookClient(nb=nb, resources=resources, km=km, **kwargs).execute()
           ^^^^^^^^^^^^^^^^^^^^^^^^^^^^^^^^^^^^^^^^^^^^^^^^^^^^^^^^^^^^^^^^^^^^^
  File "/opt/hostedtoolcache/Python/3.11.11/x64/lib/python3.11/site-packages/jupyter_core/utils/__init__.py", line 165, in wrapped
    return loop.run_until_complete(inner)
           ^^^^^^^^^^^^^^^^^^^^^^^^^^^^^^
  File "/opt/hostedtoolcache/Python/3.11.11/x64/lib/python3.11/asyncio/base_events.py", line 654, in run_until_complete
    return future.result()
           ^^^^^^^^^^^^^^^
  File "/opt/hostedtoolcache/Python/3.11.11/x64/lib/python3.11/site-packages/nbclient/client.py", line 709, in async_execute
    await self.async_execute_cell(
  File "/opt/hostedtoolcache/Python/3.11.11/x64/lib/python3.11/site-packages/nbclient/client.py", line 1062, in async_execute_cell
    await self._check_raise_for_error(cell, cell_index, exec_reply)
  File "/opt/hostedtoolcache/Python/3.11.11/x64/lib/python3.11/site-packages/nbclient/client.py", line 918, in _check_raise_for_error
    raise CellExecutionError.from_cell_and_msg(cell, exec_reply_content)
nbclient.exceptions.CellExecutionError: An error occurred while executing the following cell:
------------------
# For reference:
m21 = linopy.Model()

# Add the variables.
x = m21.add_variables(lower=0,name="x")
y = m21.add_variables(lower=0,name="y")

# Add the constraints and note the sense of the inequality.
m21.add_constraints(-x + y >= -3)
m21.add_constraints(2*x + y <= 14)
m21.add_constraints(-0.5*x + y <= 1.5)
m21.add_constraints(x >= 1)

# Add the objective function and specify it as a maximization problem.
m21.add_objective(2*x + 5*y, sense = "max")

# Solve the maximization problem.
m21.solve(solver_name="gurobi")

m21.solution
------------------


[31m---------------------------------------------------------------------------[39m
[31mAssertionError[39m                            Traceback (most recent call last)
[36mCell[39m[36m [39m[32mIn[4][39m[32m, line 18[39m
[32m     15[39m m21.add_objective([32m2[39m*x + [32m5[39m*y, sense = [33m"[39m[33mmax[39m[33m"[39m)
[32m     17[39m [38;5;66;03m# Solve the maximization problem.[39;00m
[32m---> [39m[32m18[39m [43mm21[49m[43m.[49m[43msolve[49m[43m([49m[43msolver_name[49m[43m=[49m[33;43m"[39;49m[33;43mgurobi[39;49m[33;43m"[39;49m[43m)[49m
[32m     20[39m m21.solution

[36mFile [39m[32m/opt/hostedtoolcache/Python/3.11.11/x64/lib/python3.11/site-packages/linopy/model.py:1143[39m, in [36mModel.solve[39m[34m(self, solver_name, io_api, explicit_coordinate_names, problem_fn, solution_fn, log_fn, basis_fn, warmstart_fn, keep_files, env, sanitize_zeros, sanitize_infinities, slice_size, remote, progress, **solver_options)[39m
[32m   1140[39m     solver_name = available_solvers[[32m0[39m]
[32m   1142[39m logger.info([33mf[39m[33m"[39m[33m Solve problem using [39m[38;5;132;01m{[39;00msolver_name.title()[38;5;132;01m}[39;00m[33m solver[39m[33m"[39m)
[32m-> [39m[32m1143[39m [38;5;28;01massert[39;00m solver_name [38;5;129;01min[39;00m available_solvers, [33mf[39m[33m"[39m[33mSolver [39m[38;5;132;01m{[39;00msolver_name[38;5;132;01m}[39;00m[33m not installed[39m[33m"[39m
[32m   1145[39m [38;5;66;03m# reset result[39;00m
[32m   1146[39m [38;5;28mself[39m.reset_solution()

[31mAssertionError[39m: Solver gurobi not installed

